Workbook
Name Actual: (PeriodInActual*('프로젝트 진행사항 '!$O1>0))*PeriodInPlan
Name ActualBeyond: PeriodInActual*('프로젝트 진행사항 '!$O1>0)
Name EmployeeList: [1]!Employees[담당자]
Name PercentComplete: PercentCompleteBeyond*PeriodInPlan
Name period_selected: '프로젝트 진행사항 '!$X$3
Name PeriodInActual: '프로젝트 진행사항 '!A$8=MEDIAN('프로젝트 진행사항 '!A$8,'프로젝트 진행사항 '!$O1,'프로젝트 진행사항 '!$O1+'프로젝트 진행사항 '!$P1-1)
Name PeriodInPlan: '프로젝트 진행사항 '!A$8=MEDIAN('프로젝트 진행사항 '!A$8,'프로젝트 진행사항 '!$M1,'프로젝트 진행사항 '!$M1+'프로젝트 진행사항 '!$N1-1)
Name Plan: PeriodInPlan*('프로젝트 진행사항 '!$M1>0)
Name ProjectEnd: '프로젝트 Milestone'!$L$23
Name TeamName: 'Project 정보'!$B$15:$B$32
Name valHEnd: '[2]설정 및 계산'!$C$19
Name valHStart: '[2]설정 및 계산'!$C$18
Name 프로젝트시작: '프로젝트 Milestone'!$L$21

Sheet Project 정보
F1: Task 진행 현황 | K1: 업무 지연 현황
B2: Project Name | F2: 완료 Task | G2: 진행 중 Task | H2: 진행대기 Task | I2: 전체 Task | K2: 정상 Task | L2: 일정변경 Task | M2: 지연 Task | N2: 전체 Task
F3: =COUNTIF('프로젝트 진행사항 '!$K:$K,"완료") -> 3 | G3: =COUNTIF('프로젝트 진행사항 '!$K:$K,"진행 중") -> 3 | H3: =COUNTIF('프로젝트 진행사항 '!$K:$K,"진행 대기") -> 112 | I3: =SUM(F3:H3) -> 118 | K3: =COUNTIF('프로젝트 진행사항 '!$J:$J,"정상") -> 1 | L3: =COUNTIF('프로젝트 진행사항 '!$J:$J,"일정변경") -> 0 | M3: =COUNTIF('프로젝트 진행사항 '!$J:$J,"지연") -> 0 | N3: =SUM(K3:M3) -> 1
B4: Project Code
B6: Project Leader
B8: 개발 기간
B10: 개발계획서 문서번호
B13: 프로젝트 팀원 & 업무 그룹 & 지원조직
B14: Name

Sheet 프로젝트 Milestone
B1: Milestone
B2: 시간 표시 막대
B20: 프로젝트 주요 Milestone
B21: 날짜 | C21: 중요 시점 | D21: 위치 | E21: BASELINE
B22: 44112 | C22: 프로젝트 시작 | D22: 20 | E22: =1 -> 1
B23: 44114 | C23: 개발 계획 확정 | D23: 10 | E23: =1 -> 1
B24: 44116 | C24: PDR | D24: -10 | E24: =1 -> 1
B25: 44117 | D25: 0 | E25: =1 -> 1
B26: 44118 | C26: CDR | D26: -15 | E26: =1 -> 1
B27: 44119 | C27: TRR | D27: 15 | E27: =1 -> 1
B28: 2020/20/16 | C28: QA 검증 시작 | D28: -15 | E28: =1 -> 1
B29: 44124 | C29: EMI 검증 및 & Alpha Test | D29: 15 | E29: =1 -> 1
B30: 44126 | C30: QA 검증 완료 | D30: -15 | E30: =1 -> 1
B31: 44129 | C31: FDR | D31: 20 | E31: =1 -> 1
B32: 44134 | C32: 프로젝트 종료 | D32: 15 | E32: =1 -> 1
E33: =1 -> 1
E34: =1 -> 1

Sheet 프로젝트 진행사항 
C2: 프로젝트 진행 일정표
S3: 기간 표시: | X3: 41 | AB3: 계획 | AE3: 실제 | AI3: % 완료 | AN3: 실제(계획 초과) | AV3: % 완료(계획 초과)
S4: 금주 | U4: ="W"& WEEKNUM(TODAY()) -> W41
C6: WBS | D6: Task | E6: 담당자 | F6: 시작 예정일 | G6: 완료 예정일 | H6: 실제 시작일 | I6: 실제 완료일 | J6: 지연여부 | K6: 상태 | L6: 비고 | M6: 계획 | N6: 계획 | O6: 실제 | P6: 실제 | Q6: 진도율
M7: 시작 | N7: 기간 | O7: 시작 | P7: 기간 | S7: 2020 Week
S8: 1 | T8: 2 | U8: 3 | V8: 4 | W8: 5 | X8: 6 | Y8: 7 | Z8: 8 | AA8: 9 | AB8: 10 | AC8: 11 | AD8: 12 | AE8: 13 | AF8: 14 | AG8: 15 | AH8: 16 | AI8: 17 | AJ8: 18 | AK8: 19 | AL8: 20 | AM8: 21 | AN8: 22 | AO8: 23 | AP8: 24 | AQ8: 25 | AR8: 26 | AS8: 27 | AT8: 28 | AU8: 29 | AV8: 30 | AW8: 31 | AX8: 32 | AY8: 33 | AZ8: 34 | BA8: 35 | BB8: 36 | BC8: 37 | BD8: 38 | BE8: 39 | BF8: 40 | BG8: 41 | BH8: 42 | BI8: 43 | BJ8: 44 | BK8: 45 | BL8: 46 | BM8: 47 | BN8: 48 | BO8: 49 | BP8: 50 | BQ8: 51 | BR8: 52 | BS8: 53 | BT8: 54 | BU8: 55 | BV8: 56 | BW8: 57 | BX8: 58 | BY8: 59 | BZ8: 60
D9: 개발 계획서 작성 | F9: 44105 | G9: 44196 | H9: 44112 | I9: 44196 | J9: 정상 | K9: =IF(AND(Q9>0%,Q9<100%),"진행 중",IF(Q9=0%,"진행 대기","완료")) -> 완료 | M9: =WEEKNUM(F9) -> 40 | N9: =WEEKNUM(G9-F9) -> 13 | O9: =WEEKNUM(H9) -> 41 | P9: =WEEKNUM(I9-H9) -> 12 | Q9: 1
D10: 개선 항목 식별 / 요구사항 분석 | F10: 42394 | G10: 42411 | K10: =IF(AND(Q10>0%,Q10<100%),"진행 중",IF(Q10=0%,"진행 대기","완료")) -> 진행 대기 | M10: =WEEKNUM(F10) -> 5 | N10: =WEEKNUM(G10-F10) -> 3 | O10: =WEEKNUM(H10) -> 0 | P10: =WEEKNUM(I10-H10) -> 0 | Q10: 0
D11: 생산 Wish List 작성 | F11: 42394 | G11: 42398 | K11: =IF(AND(Q11>0%,Q11<100%),"진행 중",IF(Q11=0%,"진행 대기","완료")) -> 진행 대기 | M11: =WEEKNUM(F11) -> 5 | N11: =WEEKNUM(G11-F11) -> 1 | O11: =WEEKNUM(H11) -> 0 | P11: =WEEKNUM(I11-H11) -> 0 | Q11: 0
D12: Field Issue List 작성 | F12: 42394 | G12: 42404 | K12: =IF(AND(Q12>0%,Q12<100%),"진행 중",IF(Q12=0%,"진행 대기","완료")) -> 진행 대기 | M12: =WEEKNUM(F12) -> 5 | N12: =WEEKNUM(G12-F12) -> 2 | O12: =WEEKNUM(H12) -> 0 | P12: =WEEKNUM(I12-H12) -> 0 | Q12: 0
D13: QA 개발 검증 List Up | F13: 42394 | G13: 42398 | K13: =IF(AND(Q13>0%,Q13<100%),"진행 중",IF(Q13=0%,"진행 대기","완료")) -> 진행 대기 | M13: =WEEKNUM(F13) -> 5 | N13: =WEEKNUM(G13-F13) -> 1 | O13: =WEEKNUM(H13) -> 0 | P13: =WEEKNUM(I13-H13) -> 0 | Q13: 0
D14: PM Requirements | F14: 42401 | G14: 42412 | K14: =IF(AND(Q14>0%,Q14<100%),"진행 중",IF(Q14=0%,"진행 대기","완료")) -> 진행 대기 | M14: =WEEKNUM(F14) -> 6 | N14: =WEEKNUM(G14-F14) -> 2 | O14: =WEEKNUM(H14) -> 0 | P14: =WEEKNUM(I14-H14) -> 0 | Q14: 0
D15: WBS 작성 | F15: 42394 | G15: 42412 | K15: =IF(AND(Q15>0%,Q15<100%),"진행 중",IF(Q15=0%,"진행 대기","완료")) -> 진행 대기 | M15: =WEEKNUM(F15) -> 5 | N15: =WEEKNUM(G15-F15) -> 3 | O15: =WEEKNUM(H15) -> 0 | P15: =WEEKNUM(I15-H15) -> 0 | Q15: 0
D16: 계발 계획서 발표 | F16: 42403 | G16: 42403 | K16: =IF(AND(Q16>0%,Q16<100%),"진행 중",IF(Q16=0%,"진행 대기","완료")) -> 진행 대기 | M16: =WEEKNUM(F16) -> 6 | N16: =WEEKNUM(G16-F16) -> 0 | O16: =WEEKNUM(H16) -> 0 | P16: =WEEKNUM(I16-H16) -> 0 | Q16: 0
D17: Block Diagram 작성 | F17: 42394 | G17: 42411 | K17: =IF(AND(Q17>0%,Q17<100%),"진행 중",IF(Q17=0%,"진행 대기","완료")) -> 진행 대기 | M17: =WEEKNUM(F17) -> 5 | N17: =WEEKNUM(G17-F17) -> 3 | O17: =WEEKNUM(H17) -> 0 | P17: =WEEKNUM(I17-H17) -> 0 | Q17: 0
D18: H/W Architecture | F18: 42394 | G18: 42398 | K18: =IF(AND(Q18>0%,Q18<100%),"진행 중",IF(Q18=0%,"진행 대기","완료")) -> 진행 대기 | M18: =WEEKNUM(F18) -> 5 | N18: =WEEKNUM(G18-F18) -> 1 | O18: =WEEKNUM(H18) -> 0 | P18: =WEEKNUM(I18-H18) -> 0 | Q18: 0
D19: S/W Architecture | F19: 42394 | G19: 42411 | K19: =IF(AND(Q19>0%,Q19<100%),"진행 중",IF(Q19=0%,"진행 대기","완료")) -> 진행 대기 | M19: =WEEKNUM(F19) -> 5 | N19: =WEEKNUM(G19-F19) -> 3 | O19: =WEEKNUM(H19) -> 0 | P19: =WEEKNUM(I19-H19) -> 0 | Q19: 0
D20: RF Architecture | F20: 42401 | G20: 42412 | K20: =IF(AND(Q20>0%,Q20<100%),"진행 중",IF(Q20=0%,"진행 대기","완료")) -> 진행 대기 | M20: =WEEKNUM(F20) -> 6 | N20: =WEEKNUM(G20-F20) -> 2 | O20: =WEEKNUM(H20) -> 0 | P20: =WEEKNUM(I20-H20) -> 0 | Q20: 0
D21: Connection Diagram 작성 | F21: 42403 | G21: 42411 | K21: =IF(AND(Q21>0%,Q21<100%),"진행 중",IF(Q21=0%,"진행 대기","완료")) -> 진행 대기 | M21: =WEEKNUM(F21) -> 6 | N21: =WEEKNUM(G21-F21) -> 2 | O21: =WEEKNUM(H21) -> 0 | P21: =WEEKNUM(I21-H21) -> 0 | Q21: 0
... D25: RF(NBD Part 개선) 예상 성능 검토 및 Link Budget 작성 | F25: 42404 | G25: 42419 | K25: =IF(AND(Q25>0%,Q25<100%),"진행 중",IF(Q25=0%,"진행 대기","완료")) -> 진행 대기 | M25: =WEEKNUM(F25) -> 6 | N25: =WEEKNUM(G25-F25) -> 3 | O25: =WEEKNUM(H25) -> 0 | P25: =WEEKNUM(I25-H25) -> 0 | Q25: 0
D26: RF(NBD Part 개선) 상세 설계 | F26: 42404 | G26: 42419 | K26: =IF(AND(Q26>0%,Q26<100%),"진행 중",IF(Q26=0%,"진행 대기","완료")) -> 진행 대기 | L26: Draft Version 설계 중 - Concept 결정이 필요함 | M26: =WEEKNUM(F26) -> 6 | N26: =WEEKNUM(G26-F26) -> 3 | O26: =WEEKNUM(H26) -> 0 | P26: =WEEKNUM(I26-H26) -> 0 | Q26: 0
D27: Motor 사전 적합성 검토 | F27: 42401 | G27: 42412 | K27: =IF(AND(Q27>0%,Q27<100%),"진행 중",IF(Q27=0%,"진행 대기","완료")) -> 진행 대기 | M27: =WEEKNUM(F27) -> 6 | N27: =WEEKNUM(G27-F27) -> 2 | O27: =WEEKNUM(H27) -> 0 | P27: =WEEKNUM(I27-H27) -> 0 | Q27: 0
D28: Module 개념 설계 | F28: 42401 | G28: 42412 | K28: =IF(AND(Q28>0%,Q28<100%),"진행 중",IF(Q28=0%,"진행 대기","완료")) -> 진행 대기 | M28: =WEEKNUM(F28) -> 6 | N28: =WEEKNUM(G28-F28) -> 2 | O28: =WEEKNUM(H28) -> 0 | P28: =WEEKNUM(I28-H28) -> 0 | Q28: 0
D29: Communication Protocol 설계 | F29: 42415 | G29: 42419 | K29: =IF(AND(Q29>0%,Q29<100%),"진행 중",IF(Q29=0%,"진행 대기","완료")) -> 진행 대기 | M29: =WEEKNUM(F29) -> 8 | N29: =WEEKNUM(G29-F29) -> 1 | O29: =WEEKNUM(H29) -> 0 | P29: =WEEKNUM(I29-H29) -> 0 | Q29: 0
D30: 초기 설계 검토 자료 취합 | F30: 42422 | G30: 42426 | K30: =IF(AND(Q30>0%,Q30<100%),"진행 중",IF(Q30=0%,"진행 대기","완료")) -> 진행 대기 | M30: =WEEKNUM(F30) -> 9 | N30: =WEEKNUM(G30-F30) -> 1 | O30: =WEEKNUM(H30) -> 0 | P30: =WEEKNUM(I30-H30) -> 0
D31: 제어 파트 전장 부품 선정 | F31: 42424 | G31: 42431 | K31: =IF(AND(Q31>0%,Q31<100%),"진행 중",IF(Q31=0%,"진행 대기","완료")) -> 진행 대기 | M31: =WEEKNUM(F31) -> 9 | N31: =WEEKNUM(G31-F31) -> 1 | O31: =WEEKNUM(H31) -> 0 | P31: =WEEKNUM(I31-H31) -> 0
D32: RF 파트 부품 선정 | K32: =IF(AND(Q32>0%,Q32<100%),"진행 중",IF(Q32=0%,"진행 대기","완료")) -> 진행 대기 | M32: =WEEKNUM(F32) -> 0 | N32: =WEEKNUM(G32-F32) -> 0 | O32: =WEEKNUM(H32) -> 0 | P32: =WEEKNUM(I32-H32) -> 0
D33: RF Cable & Connector | F33: 42401 | G33: 42426 | K33: =IF(AND(Q33>0%,Q33<100%),"진행 중",IF(Q33=0%,"진행 대기","완료")) -> 진행 중 | M33: =WEEKNUM(F33) -> 6 | N33: =WEEKNUM(G33-F33) -> 4 | O33: =WEEKNUM(H33) -> 0 | P33: =WEEKNUM(I33-H33) -> 0 | Q33: 0.1
D34: ETC ( RF 부품) | F34: 42401 | G34: 42426 | K34: =IF(AND(Q34>0%,Q34<100%),"진행 중",IF(Q34=0%,"진행 대기","완료")) -> 진행 중 | M34: =WEEKNUM(F34) -> 6 | N34: =WEEKNUM(G34-F34) -> 4 | O34: =WEEKNUM(H34) -> 0 | P34: =WEEKNUM(I34-H34) -> 0 | Q34: 0.1
D35: Design Review (PDR) | F35: 42431 | G35: 42431 | K35: =IF(AND(Q35>0%,Q35<100%),"진행 중",IF(Q35=0%,"진행 대기","완료")) -> 진행 대기 | M35: =WEEKNUM(F35) -> 10 | N35: =WEEKNUM(G35-F35) -> 0 | O35: =WEEKNUM(H35) -> 0 | P35: =WEEKNUM(I35-H35) -> 0
D36: Critical Design Step | F36: 42431 | G36: 42489 | K36: =IF(AND(Q36>0%,Q36<100%),"진행 중",IF(Q36=0%,"진행 대기","완료")) -> 진행 대기 | M36: =WEEKNUM(F36) -> 10 | N36: =WEEKNUM(G36-F36) -> 9 | O36: =WEEKNUM(H36) -> 0 | P36: =WEEKNUM(I36-H36) -> 0
D37: 제어부품 개선에 다른 위치변경 | F37: 42387 | G37: 42426 | K37: =IF(AND(Q37>0%,Q37<100%),"진행 중",IF(Q37=0%,"진행 대기","완료")) -> 진행 대기 | M37: =WEEKNUM(F37) -> 4 | N37: =WEEKNUM(G37-F37) -> 6 | O37: =WEEKNUM(H37) -> 0 | P37: =WEEKNUM(I37-H37) -> 0
D38: 제어보드, 전장품 케이스 배치, 검토 | F38: 42387 | G38: 42419 | K38: =IF(AND(Q38>0%,Q38<100%),"진행 중",IF(Q38=0%,"진행 대기","완료")) -> 완료 | L38: 초안 레이아웃, 전장품케이스 모델링 완료 | M38: =WEEKNUM(F38) -> 4 | N38: =WEEKNUM(G38-F38) -> 5 | O38: =WEEKNUM(H38) -> 0 | P38: =WEEKNUM(I38-H38) -> 0 | Q38: 1
D39: 각 모터 위치 변경 검토, 배치 | F39: 42394 | G39: 42405 | K39: =IF(AND(Q39>0%,Q39<100%),"진행 중",IF(Q39=0%,"진행 대기","완료")) -> 완료 | L39: 초안 레이아웃 | M39: =WEEKNUM(F39) -> 5 | N39: =WEEKNUM(G39-F39) -> 2 | O39: =WEEKNUM(H39) -> 0 | P39: =WEEKNUM(I39-H39) -> 0 | Q39: 1
D40: 케이블 패스 검토 | F40: 42415 | G40: 42426 | K40: =IF(AND(Q40>0%,Q40<100%),"진행 중",IF(Q40=0%,"진행 대기","완료")) -> 진행 중 | L40: 조인트부 PM적용방법 적용 | M40: =WEEKNUM(F40) -> 8 | N40: =WEEKNUM(G40-F40) -> 2 | O40: =WEEKNUM(H40) -> 0 | P40: =WEEKNUM(I40-H40) -> 0 | Q40: 0.1
D41: 케이블 고정부품 검토 | F41: 42401 | G41: 42405 | K41: =IF(AND(Q41>0%,Q41<100%),"진행 중",IF(Q41=0%,"진행 대기","완료")) -> 진행 대기 | L41: 미진행 | M41: =WEEKNUM(F41) -> 6 | N41: =WEEKNUM(G41-F41) -> 1 | O41: =WEEKNUM(H41) -> 0 | P41: =WEEKNUM(I41-H41) -> 0 | Q41: 0
D42: 기타 요구사항 반영 검토 | F42: 42401 | G42: 42412 | M42: =WEEKNUM(F42) -> 6 | N42: =WEEKNUM(G42-F42) -> 2 | O42: =WEEKNUM(H42) -> 0 | P42: =WEEKNUM(I42-H42) -> 0
D43: 모듈별 상세 설계 | M43: =WEEKNUM(F43) -> 0 | N43: =WEEKNUM(G43-F43) -> 0 | O43: =WEEKNUM(H43) -> 0 | P43: =WEEKNUM(I43-H43) -> 0
D44: Pedestal Control Unit | F44: 42431 | G44: 42437 | K44: =IF(AND(Q44>0%,Q44<100%),"진행 중",IF(Q44=0%,"진행 대기","완료")) -> 진행 대기 | M44: =WEEKNUM(F44) -> 10 | N44: =WEEKNUM(G44-F44) -> 1 | O44: =WEEKNUM(H44) -> 0 | P44: =WEEKNUM(I44-H44) -> 0
D45: Motor Driver Unit | F45: 42437 | G45: 42440 | K45: =IF(AND(Q45>0%,Q45<100%),"진행 중",IF(Q45=0%,"진행 대기","완료")) -> 진행 대기 | M45: =WEEKNUM(F45) -> 11 | N45: =WEEKNUM(G45-F45) -> 1 | O45: =WEEKNUM(H45) -> 0 | P45: =WEEKNUM(I45-H45) -> 0
...

Sheet TBD & Risk 관리
A1: TBD/ TBC 항목
A2: ID | B2: Description | C2: 확정 예정 일자 | D2: Status | E2: 담당자 | F2: 결정 결과 | G2: 결정 근거 | H2: 비고
A3: FB-T-01 | X3: 41
S7: 2020 Week
A30: Risk Management
A31: ID | B31: Description | C31: 식별 일자 | D31: 위험 등급 | E31: 담당자 | F31: 위험 처리 Action | H31: 위험 영향
A32: FB-R-01

Sheet Project Output List
A1: 문서관리 양식
A3: Project 명 | C3: ='Project 정보'!C2:C2 -> 0 | G3: 관리 담당자
A4: Project 코드 | C4: ='Project 정보'!C4:C4 -> 0 | G4: 최종 Update 일자 | H4: =TODAY() -> 44112
A5: 순번 | B5: 문서번호 | C5: Resivion | D5: 문서분류 | E5: 문서 형태 | F5: 문서명 | G5: Description | H5: 담당팀 | I5: 작성자 | J5: 작성일자
A6: =ROW()-5 -> 1
A7: =ROW()-5 -> 2
A8: =ROW()-5 -> 3
A9: =ROW()-5 -> 4
A10: =ROW()-5 -> 5
A11: =ROW()-5 -> 6
A12: =ROW()-5 -> 7
A13: =ROW()-5 -> 8
A15: =ROW()-5 -> 10
A16: =ROW()-5 -> 11
A17: =ROW()-5 -> 12
A18: =ROW()-5 -> 13
... A27: =ROW()-5 -> 22
